<?xml version="1.0" ?>
<robot name="library_robot" xmlns:xacro="http://ros.org/wiki/xacro">
  <link name="base_link">
    <visual>
      <geometry>
        <mesh filename="package://library_robot/mesh/visual/base_link.dae" scale="1 1 1" /> 
      </geometry>
    </visual>
    <collision>
      <geometry>
        <mesh filename="package://library_robot/mesh/collision/base_link.stl" scale="1 1 1" />
      </geometry>
    </collision>

    <inertial>
      <origin xyz="0 0 0" />
      <mass value="10.0" />
      <inertia ixx="0.1" ixy="0.0" ixz="0.0"
              iyy="0.1" iyz="0.0"
              izz="0.1" />
    </inertial>
    
  </link>

  <!-- Wheel -->
  <link name="right_wheel_link">
    <visual>
      <geometry>
        <mesh filename="package://library_robot/mesh/visual/wheel_right_trans.dae" scale="1 1 1" />  
      </geometry>
    </visual>
    <collision>
      <geometry>
        <mesh filename="package://library_robot/mesh/collision/wheel_right_trans.stl" scale="1 1 1" />
      </geometry>
    </collision> 

    <inertial>
      <origin xyz="0 0 0" />
      <mass value="0.2" />
      <inertia ixx="0.1" ixy="0.0" ixz="0.0"
              iyy="0.1" iyz="0.0"
              izz="0.1" />
    </inertial>
    
  </link>

  <link name="left_wheel_link">
    <visual>
      <geometry>
        <mesh filename="package://library_robot/mesh/visual/wheel_left_trans.dae" scale="1 1 1" />  
      </geometry>
    </visual>
    <collision>
      <geometry>
        <mesh filename="package://library_robot/mesh/collision/wheel_left_trans.stl" scale="1 1 1" />
      </geometry>
    </collision> 

    <inertial>
      <origin xyz="0 0 0" />
      <mass value="0.2" />
      <inertia ixx="0.1" ixy="0.0" ixz="0.0"
              iyy="0.1" iyz="0.0"
              izz="0.1" />
    </inertial>
    
  </link>

  <!-- Joint -->
  <joint name="right_wheel_joint" type="continuous">
    <origin xyz="0.0 -0.13 -0.502" rpy="0 0 0" />
    <axis xyz="0 1 0" />
    <parent link="base_link" />
    <child link="right_wheel_link" />
  </joint>

  <joint name="left_wheel_joint" type="continuous">    
    <origin xyz="0.0 0.13 -0.502" rpy="0 0 0" />
    <axis xyz="0 1 0" />
    <parent link="base_link" />
    <child link="left_wheel_link" />    
  </joint>


  <!-- Transmission -->
  <transmission name="tran1">
      <type>transmission_interface/SimpleTransmission</type>
      <joint name="left_wheel_joint">
          <hardwareInterface>hardware_interface/EffortJointInterface</hardwareInterface>
      </joint>
      <actuator name="motor1">
          <hardwareInterface>hardware_interface/EffortJointInterface</hardwareInterface>
          <mechanicalReduction>2</mechanicalReduction>
      </actuator>
  </transmission>

  <transmission name="tran2">
      <type>transmission_interface/SimpleTransmission</type>
      <joint name="right_wheel_joint">
          <hardwareInterface>hardware_interface/EffortJointInterface</hardwareInterface>
      </joint>
      <actuator name="motor2">
          <hardwareInterface>hardware_interface/EffortJointInterface</hardwareInterface>
          <mechanicalReduction>2</mechanicalReduction>
      </actuator>
  </transmission>


  <!-- Caster -->
  <joint name="front_caster_joint" type="fixed">
    <parent link="base_link"/>
    <child link="front_caster_link"/>
    <origin xyz="0.3 0.0 ${-0.502-0.0425}"/>        
  </joint>

  <link name="front_caster_link">
    <visual>
        <geometry>
            <sphere radius="0.03"/>
        </geometry>
        <origin xyz="0.0 0.0 0.0"/>
    </visual>
    <inertial>
        <mass value="1"/>
        <origin xyz="0.0 0.0 0.0"/>
        <inertia ixx="0.00144" ixy="0" ixz="0" iyy="0.00144" iyz="0" izz="0.00144"/>
    </inertial>
    <collision>
        <geometry>
            <sphere radius="0.03"/>
        </geometry>
        <origin xyz="0.0 0.0 0.0"/>
    </collision>
  </link>

  <joint name="rear_caster_joint" type="fixed">
    <parent link="base_link"/>
    <child link="rear_caster_link"/>
    <origin xyz="-0.3 0.0 ${-0.502-0.0425}"/>        
  </joint>

  <link name="rear_caster_link">
    <visual>
      <geometry>
          <sphere radius="0.03"/>
      </geometry>
      <origin xyz="0.0 0.0 0.0"/>
    </visual>
    <inertial>
      <mass value="1"/>
      <origin xyz="0.0 0.0 0.0"/>
      <inertia ixx="0.00144" ixy="0" ixz="0" iyy="0.00144" iyz="0" izz="0.00144"/>
    </inertial>
    <collision>
      <geometry>
          <sphere radius="0.03"/>
      </geometry>
      <origin xyz="0.0 0.0 0.0"/>
    </collision>
  </link>

  <!-- Lidar -->
  <joint name="base_link_to_lidar_link" type="fixed">
    <parent link="base_link"/>
    <child link="lidar_link"/>
    <origin xyz="0.12 0.0 -0.152" rpy="0 0 3.1413" />        
  </joint>

  <link name="lidar_link">
    <visual>
        <geometry>
          <cylinder radius="0.03" length="0.02"/>
        </geometry>
        <origin xyz="0.0 0.0 0.0"/>
    </visual>
    <inertial>
        <mass value="0.2"/>
        <origin xyz="0.0 0.0 0.0"/>
        <inertia ixx="0.00144" ixy="0" ixz="0" iyy="0.00144" iyz="0" izz="0.00144"/>
    </inertial>
    <collision>
        <geometry>
            <cylinder radius="0.03" length="0.02"/>
        </geometry>
        <origin xyz="0.0 0.0 0.0"/>
    </collision>
  </link>

  <!-- Camera -->
  <joint name="base_link_to_camera_link" type="fixed">
    <parent link="base_link"/>
    <child link="camera_link"/>
    <origin xyz="0.33 0.0 -0.24" rpy="0 0 0" />      
  </joint>

  <link name="camera_link">
    <visual>
        <geometry>
          <box size="0.1 0.06 0.02" />
        </geometry>
        <origin xyz="0.0 0.0 0.0"/>
    </visual>
    <inertial>
        <mass value="0.1"/>
        <origin xyz="0.0 0.0 0.0"/>
        <inertia ixx="0.00144" ixy="0" ixz="0" iyy="0.00144" iyz="0" izz="0.00144"/>
    </inertial>
    <collision>
        <geometry>
            <box size="0.1 0.06 0.02" />
        </geometry>
        <origin xyz="0.0 0.0 0.0"/>
    </collision>
  </link>

  <!-- Map -->
  <!-- <link name="map">
    <origin xyz="0 0 0" rpy="0 0 0" />
  </link>

  <joint name="virtual_map_right" type="fixed">
    <origin xyz="0.0 0.1547 -0.502" />
    <parent link="map" />
    <child link="right_wheel_link" />
  </joint>

  <joint name="virtual_map_left" type="fixed">
    <origin xyz="0.0 -0.1547 -0.502" />
    <parent link="map" />
    <child link="left_wheel_link" />
  </joint> -->

</robot>
